<mujoco>
  <compiler angle="radian"
          inertiafromgeom="true"
          texturedir="textures/"/>
  <default>
      <site type="sphere" rgba=".9 .1 .9 1" size="0.001"/>
      <geom rgba=".1 .5 .2 1"/>
  </default>

<option timestep="0.01" />

  <asset>
    <material name="MatGnd" specular=".3" shininess=".3" reflectance="0.3" rgba=".5 .55 .5 1"/>
    <mesh name="body1" file="meshes/sensor_top.STL" scale=".001 .001 .001"/>
    <mesh name="body0" file="meshes/long_sensor_top.STL" scale=".001 .001 .001"/>
    <mesh name="tip" file="meshes/tip.STL" scale=".001 .001 .001"/>
    <mesh name="tip2" file="meshes/tip_2.STL" scale=".001 .001 .001"/>
  </asset>
   <worldbody>

     <light directional="true" cutoff="40" exponent="10" diffuse=".4 .4 .4" specular=".7 .7 .7" pos="0 0 1.5" dir="0 0 -1"/>
     <geom name="tableTop" material="MatGnd" type="plane"  size="0.4 0.3 0.2" rgba=".6 .6 .5 1" contype="1" conaffinity="1"/>

     <body name="item" pos="0.08 0.09 0.07" >
       <geom type="cylinder" size="0.04 0.07"  rgba="0.7 0 0 1" mass="0.1"/>
       <site name="object" rgba="0 1 1 1 "/>
       <site name="object_top" pos="0 0 0.07" rgba="0 1 1 1 "/>
       <joint type="free" />

     </body>

      <body name="base" pos="0 0 0">

          <geom type="box" size="0.12 0.05 0.07" pos="0 -0.062 0.07" />
          <body name="right" pos="0.051438 0 0.09795">

            <!-- <inertial pos="0 0 0" mass="0.0297" /> -->

            <geom type="mesh" mesh="body0" euler="1.57 0 0" pos="-0.02313777 0.01214 0.0032" mass="0.01485"/>
            <geom type="mesh" mesh="body0" euler="1.57 0 0" pos="-0.02313777 0.01214 -0.01585" mass="0.01485"/>
            <geom name ="spool_0" type="cylinder" size="0.001 0.01" euler="0 0 0" pos="-0.02038789 -0.00223829 0"/>
            <site name="site0" pos="-0.02038789 -0.00173829 0"/>
            <body name="right_1" pos="0 0.042141198166 0" >
              <!-- <inertial pos="0 0 0" mass="0.025" /> -->
              <geom type="mesh" mesh="body1" euler="0 0 0" pos="-0.0108 -0.017184 0.0032" mass="0.0125"/>
              <geom type="mesh" mesh="body1" euler="0 0 0" pos="-0.0108 -0.017184 -0.01085" mass="0.0125"/>
              <geom name ="spool_1" type="cylinder" size="0.001 0.01" euler="0 0 0" pos="-0.00828 -0.00988 0"/>
              <joint name="joint0" type="hinge" pos="0 -0.042141198166 0" limited="true" range="-0.785398 0.785398" stiffness="0.0128" springref="-1.81461882" damping="0.03"/>
              <site name="site1" pos="-0.00817 -0.00988 0"/>
              <body name="right_2" pos="0 0.0371412 0" >
                  <!-- <inertial pos="0 0 0" mass="0.025" /> -->
                  <geom type="mesh" mesh="body1" euler="0 0 0" pos="-0.0108 -0.017184 0.0032" mass="0.0125"/>
                  <geom type="mesh" mesh="body1" euler="0 0 0" pos="-0.0108 -0.017184 -0.01085" mass="0.0125"/>
                  <geom name ="spool_2" type="cylinder" size="0.001 0.01" euler="0 0 0" pos="-0.00828 -0.00988 0"/>
                  <site name="site2" pos="-0.00867 -0.00988 0"/>
                  <site name="torque_site" pos="0 -0.0371412 0"/>
                  <joint name="joint1" type="hinge" pos="0 -0.0371412 0" limited="true" range="0 1.57" stiffness="0.0128" springref="-1.029" damping="0.03"/>
                  <body name="right_finger" pos="0.0089308 0.034505 -0.00275" >
                    <!-- <inertial pos="0 0 0" mass="0.0157" /> -->
                    <body name ="r_sensor" euler="0 -1.57 0" pos="0 0 0">
                      <geom type="mesh" mesh="tip2" euler="0 1.57 0"  pos="-0.015992 -0.014547 0.025959" mass="0.0157"/>
                      <!-- <geom type="mesh" mesh="tip" euler="0 1.57 0"  pos="-0.0139921 -0.0145474  0.0154308" rgba=".1 .5 .2 0.4"/> -->
                      <site name="site3" pos="0.00175 -0.0195474 0.0154308"/>
                      <site name="site4" pos="0.00175 -0.0195474 0.0034308"/>
                      <site name="site5" pos="0.00175 -0.0145474 -0.0204308"/>
                      <site name="site6" pos="0.00275 -0.0075474 -0.0204308"/>
                      <joint name="joint2" type="hinge" axis="1 0 0" pos="0.00275 -0.034505  0.0089308" limited="true" range="0 1.57" stiffness="0.0128" springref="-1.029" damping="0.03"/>


                      <site name="r_sensor_1_b" pos="0.00275 -0.0088759 0.0109516" euler="0 0 0"/>
                      <site name="r_sensor_2_b" pos="0.00275 -0.0010084 0.0092074" euler="-0.436332 0 0"/>
                      <site name="r_sensor_3_b" pos="0.00275  0.0053848 0.0043017" euler="-0.872665 0 0"/>
                      <site name="r_sensor_4_b" pos=" 0.00275  0.0091058 -0.0028462" euler="-1.309 0 0"/>


                    </body>


                  </body>
              </body>
            </body>
          </body>


          <body name="left" pos="-0.051438 0 0.09795" euler="0 3.14 0" >
            <!-- <inertial pos="0 0 0" mass="0.0297" /> -->
            <geom type="mesh" mesh="body0" euler="1.57 0 0" pos="-0.02313777 0.01214 0.0032" mass="0.01485"/>
            <geom type="mesh" mesh="body0" euler="1.57 0 0" pos="-0.02313777 0.01214 -0.01585" mass="0.01485"/>
            <geom name ="l_spool_0" type="cylinder" size="0.001 0.01" euler="0 0 0" pos="-0.02038789 -0.00223829 0"/>
            <site name="l_site0" pos="-0.02038789 -0.00173829 0"/>
            <body name="left_1" pos="0 0.042141198166 0">
              <!-- <inertial pos="0 0 0" mass="0.025" /> -->
              <geom type="mesh" mesh="body1" euler="0 0 0" pos="-0.0108 -0.017184 0.0032" mass="0.0125" />
              <geom type="mesh" mesh="body1" euler="0 0 0" pos="-0.0108 -0.017184 -0.01085" mass="0.0125"/>
              <geom name ="l_spool_1" type="cylinder" size="0.001 0.01" euler="0 0 0" pos="-0.00828 -0.00988 0"/>
              <joint axis="0 0 -1" name="l_joint0" type="hinge" pos="0 -0.042141198166 0" limited="true" ref="0" range="-0.785398 0.785398" stiffness="0.0128" springref="1.81461882" damping="0.03"/>
              <site name="l_site1" pos="-0.00817 -0.00988 0"/>
              <body name="left_2" pos="0 0.0371412 0">
                  <!-- <inertial pos="0 0 0" mass="0.025" /> -->
                  <geom type="mesh" mesh="body1" euler="0 0 0" pos="-0.0108 -0.017184 0.0032" mass="0.0125"/>
                  <geom type="mesh" mesh="body1" euler="0 0 0" pos="-0.0108 -0.017184 -0.01085" mass="0.0125"/>
                  <geom name ="l_spool_2" type="cylinder" size="0.001 0.01" euler="0 0 0" pos="-0.00828 -0.00988 0"/>
                  <site name="l_site2" pos="-0.00867 -0.00988 0"/>
                  <joint axis="0 0 -1" name="l_joint1" type="hinge" pos="0 -0.0371412 0" limited="true" range="-1.57 0" stiffness="0.0128" springref="1.029" damping="0.03"/>
                  <body name="left_finger" pos="0.0089308 0.034505 -0.00275">
                      <!-- <inertial pos="0 0 0" mass="0.0157"/> -->
                      <body name ="l_sensor" euler="0 -1.57 0" pos="0 0 0">
                      <geom type="mesh" mesh="tip2" euler="0 1.57 0"  pos="-0.015992 -0.014547 0.025959" mass="0.0157"/>
                      <!-- <geom type="mesh" mesh="tip" euler="0 1.57 0"  pos="-0.0139921 -0.0145474  0.0154308" rgba=".1 .5 .2 0.4"/> -->
                      <site name="l_site3" pos="0.00175 -0.0195474 0.0154308"/>
                      <site name="l_site4" pos="0.00175 -0.0195474 0.0034308"/>
                      <site name="l_site5" pos="0.00175 -0.0145474 -0.0204308"/>
                      <site name="l_site6" pos="0.00275 -0.0075474 -0.0204308"/>
                      <joint axis="-1 0 0" name="l_joint2" type="hinge"  pos="0.00275 -0.034505  0.0089308" limited="true" range="-1.57 0" stiffness="0.0128" springref="1.029" damping="0.03"/>

                      <site name="l_sensor_1_b" pos="0.00275 -0.0088759 0.0109516" euler="0 0 0"/>
                      <site name="l_sensor_2_b" pos="0.00275 -0.0010084 0.0092074" euler="-0.436332 0 0"/>
                      <site name="l_sensor_3_b" pos="0.00275  0.0053848 0.0043017" euler="-0.872665 0 0"/>
                      <site name="l_sensor_4_b" pos=" 0.00275  0.0091058 -0.0028462" euler="-1.309 0 0"/>


                    </body>

                  </body>
              </body>
            </body>

          </body>
      </body>



      <!-- <body name="goal" pos="-0.08 0.1 0.07" >
        <site name="target" type="cylinder" size="0.04 0.07" rgba=" .9 .1 .1 .1" />

      </body> -->

      <body name="goal" pos="0.08 0.1 0.07" >
        <site name="target" type="cylinder" size="0.04 0.07" rgba=" .9 .1 .1 .1" />

      </body>

   </worldbody>

   <tendon>
           <spatial name="tendon1" width="0.0002" rgba=".95 .3 .3 1" >
                  <site site="site0"/>
                  <site site="site1"/>
                  <site site="site2"/>
                  <site site="site3"/>
                  <site site="site4"/>
                  <site site="site5"/>
                  <site site="site6"/>

             </spatial>

             <spatial name="tendon2" width="0.0002" rgba=".95 .3 .3 1" >
                    <site site="l_site0"/>
                    <site site="l_site1"/>
                    <site site="l_site2"/>
                    <site site="l_site3"/>
                    <site site="l_site4"/>
                    <site site="l_site5"/>
                    <site site="l_site6"/>

               </spatial>
 </tendon>

 <actuator>
    <motor name="Right" tendon="tendon1" ctrllimited="true" ctrlrange="-1 0" gear="20"  />
    <motor name="Left" tendon="tendon2" ctrllimited="true" ctrlrange="-1 0" gear="20" />
 </actuator>


</mujoco>
